Traceback (most recent call last):
  File "/home/sarah-schaefers/anaconda3/envs/jb/lib/python3.10/site-packages/jupyter_core/utils/__init__.py", line 154, in wrapped
    asyncio.get_running_loop()
RuntimeError: no running event loop

During handling of the above exception, another exception occurred:

Traceback (most recent call last):
  File "/home/sarah-schaefers/anaconda3/envs/jb/lib/python3.10/site-packages/jupyter_cache/executors/utils.py", line 58, in single_nb_execution
    executenb(
  File "/home/sarah-schaefers/anaconda3/envs/jb/lib/python3.10/site-packages/nbclient/client.py", line 1319, in execute
    return NotebookClient(nb=nb, resources=resources, km=km, **kwargs).execute()
  File "/home/sarah-schaefers/anaconda3/envs/jb/lib/python3.10/site-packages/jupyter_core/utils/__init__.py", line 158, in wrapped
    return loop.run_until_complete(inner)
  File "/home/sarah-schaefers/anaconda3/envs/jb/lib/python3.10/asyncio/base_events.py", line 649, in run_until_complete
    return future.result()
  File "/home/sarah-schaefers/anaconda3/envs/jb/lib/python3.10/site-packages/nbclient/client.py", line 709, in async_execute
    await self.async_execute_cell(
  File "/home/sarah-schaefers/anaconda3/envs/jb/lib/python3.10/site-packages/nbclient/client.py", line 1062, in async_execute_cell
    await self._check_raise_for_error(cell, cell_index, exec_reply)
  File "/home/sarah-schaefers/anaconda3/envs/jb/lib/python3.10/site-packages/nbclient/client.py", line 918, in _check_raise_for_error
    raise CellExecutionError.from_cell_and_msg(cell, exec_reply_content)
nbclient.exceptions.CellExecutionError: An error occurred while executing the following cell:
------------------
co2_countries_only = co2_2023[co2_2023['iso_code'].str.len() == 3]
top_emitters = co2_countries_only.groupby('country')['co2'].sum().sort_values(ascending=False)
top10 = top_emitters.head(10)

plt.figure(figsize=(10,6))
top10.plot(kind='bar')
plt.title('Top 10 landen met hoogste COâ‚‚-uitstoot in 2023')
plt.ylabel('COâ‚‚-uitstoot (miljoen ton)')
plt.xlabel('Land')
plt.xticks(rotation=45, ha='right')
plt.grid(axis='y')
plt.tight_layout()
plt.show()
------------------


[0;31m---------------------------------------------------------------------------[0m
[0;31mNameError[0m                                 Traceback (most recent call last)
Cell [0;32mIn[1], line 1[0m
[0;32m----> 1[0m co2_countries_only [38;5;241m=[39m [43mco2_2023[49m[co2_2023[[38;5;124m'[39m[38;5;124miso_code[39m[38;5;124m'[39m][38;5;241m.[39mstr[38;5;241m.[39mlen() [38;5;241m==[39m [38;5;241m3[39m]
[1;32m      2[0m top_emitters [38;5;241m=[39m co2_countries_only[38;5;241m.[39mgroupby([38;5;124m'[39m[38;5;124mcountry[39m[38;5;124m'[39m)[[38;5;124m'[39m[38;5;124mco2[39m[38;5;124m'[39m][38;5;241m.[39msum()[38;5;241m.[39msort_values(ascending[38;5;241m=[39m[38;5;28;01mFalse[39;00m)
[1;32m      3[0m top10 [38;5;241m=[39m top_emitters[38;5;241m.[39mhead([38;5;241m10[39m)

[0;31mNameError[0m: name 'co2_2023' is not defined

